<?xml version="1.0" ?>
<sdf version="1.4">
	<model name="my_robot">
	<static>false</static>
	
	<link name="camera">
		<pose>.0 .0 .25 .0 .0 .0</pose>
		<inertial>
        		<mass>0.1</mass>
      		</inertial>
		<collision name="camera_collision">
		        <geometry>
			        <box>
				        <size>0.1 0.1 0.1</size>
			          </box>
		        </geometry>
		</collision>
		<visual name="camera_visual">
		        <geometry>
			          <box>
            				<size>0.1 0.1 0.1</size>
			          </box>
		        </geometry>
		</visual>
		<sensor name="camera" type="camera">
			<always_on>true</always_on>
		        <update_rate>1</update_rate>
		        <visualize>true</visualize>
			<camera>
	                    <horizontal_fov>1.047</horizontal_fov>
			       <image>
			            <width>640</width>
			            <height>480</height>
			       </image>
		              <clip>
			            <near>0.1</near>
		        	    <far>100</far>
			      </clip>
		        </camera>
	      </sensor>

	</link>
	<link name="chassis">
		<pose>0 0 .1 0 0 0</pose>
		<collision name="collision">
			<geometry>
				<box>
					<size>.4 .2 .1</size>
				</box>
			</geometry>
		</collision>
		
		<visual name ="visual">
			<geometry>
				<box>
					<size>.4 .2 .1</size>
				</box>
			</geometry>
		</visual>
		
	</link>	

	<link name="left_wheel">
		<pose>0.1 0.13 0.1 0 1.5707 1.5707</pose>
		<collision name="collision">
			<geometry>
				<cylinder>
					<radius>.09</radius>
					<length>.05</length>
				</cylinder>
			</geometry>
		</collision>
		
		<visual name="visual">
			<geometry>
				<cylinder>
					<radius>.09</radius>
					<length>.05</length>
				</cylinder>
			</geometry>
		</visual>
	</link>
	
	<link name="right_wheel">
		<pose>0.1 -0.13 0.1 0 1.5707 1.5707</pose>
		<collision name="collision">
			<geometry>
				<cylinder>
					<radius>.09</radius>
					<length>.05</length>
				</cylinder>
			</geometry>
		</collision>
		
		<visual name="visual">
			<geometry>
				<cylinder>
					<radius>.09</radius>
					<length>.05</length>
				</cylinder>
			</geometry>
		</visual>
	</link>

	<link name="left_wheelA">
		<pose>-0.1 0.13 0.1 0 1.5707 1.5707</pose>
		<collision name="collision">
			<geometry>
				<cylinder>
					<radius>.09</radius>
					<length>.05</length>
				</cylinder>
			</geometry>
		</collision>
		
		<visual name="visual">
			<geometry>
				<cylinder>
					<radius>.09</radius>
					<length>.05</length>
				</cylinder>
			</geometry>
		</visual>
	</link>
	
	<link name="right_wheelA">
		<pose>-0.1 -0.13 0.1 0 1.5707 1.5707</pose>
		<collision name="collision">
			<geometry>
				<cylinder>
					<radius>.09</radius>
					<length>.05</length>
				</cylinder>
			</geometry>
		</collision>
		
		<visual name="visual">
			<geometry>
				<cylinder>
					<radius>.09</radius>
					<length>.05</length>
				</cylinder>
			</geometry>
		</visual>
	</link>
	
	<joint type="revolute" name="camera">
		<pose>0 0 0.3 0 0 0</pose>
		<child>camera</child>
		<parent>chassis</parent>
		<axis>
			<xyz>0 1 0</xyz>
		</axis>
	</joint>
	
	<joint type="revolute" name="left_wheel_hinger">
		<pose>0 0 0.03 0 0 0</pose>
		<child>left_wheel</child>
		<parent>chassis</parent>
		<axis>
			<xyz>0 1 0</xyz>
		</axis>
	</joint>

	<joint type="revolute" name="right_wheel_hinger">
		<pose>0 0 0.03 0 0 0</pose>
		<child>right_wheel</child>
		<parent>chassis</parent>
		<axis>
			<xyz>0 1 0</xyz>
		</axis>
	</joint>

	<joint type="revolute" name="left_wheel_hingerA">
		<pose>0 0 0.03 0 0 0</pose>
		<child>left_wheelA</child>
		<parent>chassis</parent>
		<axis>
			<xyz>0 1 0</xyz>
		</axis>
	</joint>

	<joint type="revolute" name="right_wheel_hingerA">
		<pose>0 0 0.03 0 0 0</pose>
		<child>right_wheelA</child>
		<parent>chassis</parent>
		<axis>
			<xyz>0 1 0</xyz>
		</axis>
	</joint>

	
	</model>
</sdf>
